# Visitor Failure Report — 2025-10-13T17:01:27.906360+00:00

- Workspace root: `C:\x_runner_x`
- Run started at: 2025-10-13T17:00:05.346884+00:00
- Run completed at: 2025-10-13T17:01:27.906227+00:00
- Total repositories examined: 14
- Total tool executions: 70
- Failing tool executions: 30
- Cache hits: 2

## Failures

- [ ] `x_0_make_all_x` · `black` — black failed for x_0_make_all_x (exit 1) cwd: C:\x_runner_x\x_0_make_all_x command: C:\Users\eye43\AppData\Local\Programs\Python\Python313\python.exe -m black . --line-length 88 --target-version py311 --check --diff started_at: 2025-10-13T…
  - Command: `C:\Users\eye43\AppData\Local\Programs\Python\Python313\python.exe -m black . --line-length 88 --target-version py311 --check --diff`
  - Exit: exit 1
  - Repo path: `C:\x_runner_x\x_0_make_all_x`
  - Tool version: python -m black, 25.9.0 (compiled: yes)
Python (CPython) 3.13.7
  - Captured at: 2025-10-13T17:00:12.174750+00:00
  - Suggested action: Investigate
  - Stdout preview:
    > --- C:\x_runner_x\x_0_make_all_x\x_cls_make_all_x.py	2025-10-13 16:57:47.560279+00:00
    > +++ C:\x_runner_x\x_0_make_all_x\x_cls_make_all_x.py	2025-10-13 17:00:11.893284+00:00
    > @@ -99,10 +99,12 @@
    >      publish_opts: Mapping[str, object] | None
    >  
    > …
  - Stderr preview:
    > would reformat C:\x_runner_x\x_0_make_all_x\x_cls_make_all_x.py
    > 
    > Oh no! \U0001f4a5 \U0001f494 \U0001f4a5
    > 1 file would be reformatted, 13 files would be left unchanged.

- [ ] `x_0_make_all_x` · `mypy` — mypy failed for x_0_make_all_x (exit 1) cwd: C:\x_runner_x\x_0_make_all_x command: C:\Users\eye43\AppData\Local\Programs\Python\Python313\python.exe -m mypy . --strict --no-warn-unused-configs --show-error-codes --warn-return-any --warn-un…
  - Command: `C:\Users\eye43\AppData\Local\Programs\Python\Python313\python.exe -m mypy . --strict --no-warn-unused-configs --show-error-codes --warn-return-any --warn-unreachable --disallow-any-unimported --disallow-any-expr --disallow-any-decorated --disallow-any-explicit`
  - Exit: exit 1
  - Repo path: `C:\x_runner_x\x_0_make_all_x`
  - Tool version: mypy 3.4.3 (compiled: yes)
  - Captured at: 2025-10-13T17:00:13.087110+00:00
  - Suggested action: Investigate
  - Stdout preview:
    > C:\x_runner_x\x_make_pip_updates_x\update_flow.py:19: error: Explicit "Any" is not allowed  [explicit-any]
    > C:\x_runner_x\x_make_pip_updates_x\update_flow.py:256: error: Incompatible types in assignment (expression has type "Generator[tuple[str, None], None, None]", variable has type "ItemsView[str, str | None]")  [assignment]
    > C:\x_runner_x\x_make_pip_updates_x\update_flow.py:144: error: Unused "type: ignore" comment  [unused-ignore]
    > C:\x_runner_x\x_make_github_visitor_x\inspection_flow.py:34: error: Expression type contains "Any" (has type "Any | None")  [misc]
    > C:\x_runner_x\x_make_github_visitor_x\inspection_flow.py:35: error: Expression type contains "Any" (has type "Any | None")  [misc]
    > …

- [ ] `x_0_make_all_x` · `pyright` — pyright failed for x_0_make_all_x (exit 1) cwd: C:\x_runner_x\x_0_make_all_x command: C:\Users\eye43\AppData\Local\Programs\Python\Python313\python.exe -m pyright . --level error started_at: 2025-10-13T17:00:13.087656+00:00 duration: 0.268…
  - Command: `C:\Users\eye43\AppData\Local\Programs\Python\Python313\python.exe -m pyright . --level error`
  - Exit: exit 1
  - Repo path: `C:\x_runner_x\x_0_make_all_x`
  - Tool version: <exit 1> Traceback (most recent call last):
  File "<frozen runpy>", line 198, in _run_module_as_main
  File "<frozen runpy>", line 88, in _run_code
  File "C:\Users\eye43\AppData\Local\Programs\Python\Python313\Lib\site-packages\pyright\__main__.py", line 1, in <module>
    from fastapi.cli import main
  File "C:\Users\eye43\AppData\Local\Programs\Python\Python313\Lib\site-packages\fastapi\__init__.py", line 7, in <module>
    from .applications import FastAPI as FastAPI
  File "C:\Users\eye43\AppData\Local\Programs\Python\Python313\Lib\site-packages\fastapi\applications.py", line 16, in <module>
    from fastapi import routing
  File "C:\Users\eye43\AppData\Local\Programs\Python\Python313\Lib\site-packages\fastapi\routing.py", line 24, in <module>
    from fastapi.dependencies.models import Dependant
  File "C:\Users\eye43\AppData\Local\Programs\Python\Python313\Lib\site-packages\fastapi\dependencies\models.py", line 3, in <module>
    from fastapi.security.base import SecurityBase
  File "C:\Users\eye43\AppData\Local\Programs\Python\Python313\Lib\site-packages\fastapi\security\__init__.py", line 1, in <module>
    from .api_key import APIKeyCookie as APIKeyCookie
  File "C:\Users\eye43\AppData\Local\Programs\Python\Python313\Lib\site-packages\fastapi\security\api_key.py", line 3, in <module>
    from fastapi.openapi.models import APIKey, APIKeyIn
  File "C:\Users\eye43\AppData\Local\Programs\Python\Python313\Lib\site-packages\fastapi\openapi\models.py", line 103, in <module>
    class Schema(BaseModel):
    ...<38 lines>...
            extra: str = "allow"
  File "C:\Users\eye43\AppData\Local\Programs\Python\Python313\Lib\site-packages\pydantic\main.py", line 286, in __new__
    cls.__try_update_forward_refs__()
    ~~~~~~~~~~~~~~~~~~~~~~~~~~~~~~~^^
  File "C:\Users\eye43\AppData\Local\Programs\Python\Python313\Lib\site-packages\pydantic\main.py", line 808, in __try_update_forward_refs__
    update_model_forward_refs(cls, cls.__fields__.values(), cls.__config__.json_encoders, localns, (NameError,))
    ~~~~~~~~~~~~~~~~~~~~~~~~~^^^^^^^^^^^^^^^^^^^^^^^^^^^^^^^^^^^^^^^^^^^^^^^^^^^^^^^^^^^^^^^^^^^^^^^^^^^^^^^^^^^
  File "C:\Users\eye43\AppData\Local\Programs\Python\Python313\Lib\site-packages\pydantic\typing.py", line 554, in update_model_forward_refs
    update_field_forward_refs(f, globalns=globalns, localns=localns)
    ~~~~~~~~~~~~~~~~~~~~~~~~~^^^^^^^^^^^^^^^^^^^^^^^^^^^^^^^^^^^^^^^
  File "C:\Users\eye43\AppData\Local\Programs\Python\Python313\Lib\site-packages\pydantic\typing.py", line 520, in update_field_forward_refs
    field.type_ = evaluate_forwardref(field.type_, globalns, localns or None)
                  ~~~~~~~~~~~~~~~~~~~^^^^^^^^^^^^^^^^^^^^^^^^^^^^^^^^^^^^^^^^
  File "C:\Users\eye43\AppData\Local\Programs\Python\Python313\Lib\site-packages\pydantic\typing.py", line 66, in evaluate_forwardref
    return cast(Any, type_)._evaluate(globalns, localns, set())
           ~~~~~~~~~~~~~~~~~~~~~~~~~~^^^^^^^^^^^^^^^^^^^^^^^^^^
TypeError: ForwardRef._evaluate() missing 1 required keyword-only argument: 'recursive_guard'
  - Captured at: 2025-10-13T17:00:13.355333+00:00
  - Suggested action: Investigate
  - Stderr preview:
    > Traceback (most recent call last):
    >   File "<frozen runpy>", line 198, in _run_module_as_main
    >   File "<frozen runpy>", line 88, in _run_code
    >   File "C:\Users\eye43\AppData\Local\Programs\Python\Python313\Lib\site-packages\pyright\__main__.py", line 1, in <module>
    >     from fastapi.cli import main
    > …

- [ ] `x_legatus_acta_schedae_x` · `pyright` — pyright failed for x_legatus_acta_schedae_x (exit 1) cwd: C:\x_runner_x\x_legatus_acta_schedae_x command: C:\Users\eye43\AppData\Local\Programs\Python\Python313\python.exe -m pyright . --level error started_at: 2025-10-13T17:00:18.669882+0…
  - Command: `C:\Users\eye43\AppData\Local\Programs\Python\Python313\python.exe -m pyright . --level error`
  - Exit: exit 1
  - Repo path: `C:\x_runner_x\x_legatus_acta_schedae_x`
  - Tool version: <exit 1> Traceback (most recent call last):
  File "<frozen runpy>", line 198, in _run_module_as_main
  File "<frozen runpy>", line 88, in _run_code
  File "C:\Users\eye43\AppData\Local\Programs\Python\Python313\Lib\site-packages\pyright\__main__.py", line 1, in <module>
    from fastapi.cli import main
  File "C:\Users\eye43\AppData\Local\Programs\Python\Python313\Lib\site-packages\fastapi\__init__.py", line 7, in <module>
    from .applications import FastAPI as FastAPI
  File "C:\Users\eye43\AppData\Local\Programs\Python\Python313\Lib\site-packages\fastapi\applications.py", line 16, in <module>
    from fastapi import routing
  File "C:\Users\eye43\AppData\Local\Programs\Python\Python313\Lib\site-packages\fastapi\routing.py", line 24, in <module>
    from fastapi.dependencies.models import Dependant
  File "C:\Users\eye43\AppData\Local\Programs\Python\Python313\Lib\site-packages\fastapi\dependencies\models.py", line 3, in <module>
    from fastapi.security.base import SecurityBase
  File "C:\Users\eye43\AppData\Local\Programs\Python\Python313\Lib\site-packages\fastapi\security\__init__.py", line 1, in <module>
    from .api_key import APIKeyCookie as APIKeyCookie
  File "C:\Users\eye43\AppData\Local\Programs\Python\Python313\Lib\site-packages\fastapi\security\api_key.py", line 3, in <module>
    from fastapi.openapi.models import APIKey, APIKeyIn
  File "C:\Users\eye43\AppData\Local\Programs\Python\Python313\Lib\site-packages\fastapi\openapi\models.py", line 103, in <module>
    class Schema(BaseModel):
    ...<38 lines>...
            extra: str = "allow"
  File "C:\Users\eye43\AppData\Local\Programs\Python\Python313\Lib\site-packages\pydantic\main.py", line 286, in __new__
    cls.__try_update_forward_refs__()
    ~~~~~~~~~~~~~~~~~~~~~~~~~~~~~~~^^
  File "C:\Users\eye43\AppData\Local\Programs\Python\Python313\Lib\site-packages\pydantic\main.py", line 808, in __try_update_forward_refs__
    update_model_forward_refs(cls, cls.__fields__.values(), cls.__config__.json_encoders, localns, (NameError,))
    ~~~~~~~~~~~~~~~~~~~~~~~~~^^^^^^^^^^^^^^^^^^^^^^^^^^^^^^^^^^^^^^^^^^^^^^^^^^^^^^^^^^^^^^^^^^^^^^^^^^^^^^^^^^^
  File "C:\Users\eye43\AppData\Local\Programs\Python\Python313\Lib\site-packages\pydantic\typing.py", line 554, in update_model_forward_refs
    update_field_forward_refs(f, globalns=globalns, localns=localns)
    ~~~~~~~~~~~~~~~~~~~~~~~~~^^^^^^^^^^^^^^^^^^^^^^^^^^^^^^^^^^^^^^^
  File "C:\Users\eye43\AppData\Local\Programs\Python\Python313\Lib\site-packages\pydantic\typing.py", line 520, in update_field_forward_refs
    field.type_ = evaluate_forwardref(field.type_, globalns, localns or None)
                  ~~~~~~~~~~~~~~~~~~~^^^^^^^^^^^^^^^^^^^^^^^^^^^^^^^^^^^^^^^^
  File "C:\Users\eye43\AppData\Local\Programs\Python\Python313\Lib\site-packages\pydantic\typing.py", line 66, in evaluate_forwardref
    return cast(Any, type_)._evaluate(globalns, localns, set())
           ~~~~~~~~~~~~~~~~~~~~~~~~~~^^^^^^^^^^^^^^^^^^^^^^^^^^
TypeError: ForwardRef._evaluate() missing 1 required keyword-only argument: 'recursive_guard'
  - Captured at: 2025-10-13T17:00:18.931570+00:00
  - Suggested action: Investigate
  - Stderr preview:
    > Traceback (most recent call last):
    >   File "<frozen runpy>", line 198, in _run_module_as_main
    >   File "<frozen runpy>", line 88, in _run_code
    >   File "C:\Users\eye43\AppData\Local\Programs\Python\Python313\Lib\site-packages\pyright\__main__.py", line 1, in <module>
    >     from fastapi.cli import main
    > …

- [ ] `x_make_common_x` · `pyright` — pyright failed for x_make_common_x (exit 1) cwd: C:\x_runner_x\x_make_common_x command: C:\Users\eye43\AppData\Local\Programs\Python\Python313\python.exe -m pyright . --level error started_at: 2025-10-13T17:00:21.359417+00:00 duration: 0.2…
  - Command: `C:\Users\eye43\AppData\Local\Programs\Python\Python313\python.exe -m pyright . --level error`
  - Exit: exit 1
  - Repo path: `C:\x_runner_x\x_make_common_x`
  - Tool version: <exit 1> Traceback (most recent call last):
  File "<frozen runpy>", line 198, in _run_module_as_main
  File "<frozen runpy>", line 88, in _run_code
  File "C:\Users\eye43\AppData\Local\Programs\Python\Python313\Lib\site-packages\pyright\__main__.py", line 1, in <module>
    from fastapi.cli import main
  File "C:\Users\eye43\AppData\Local\Programs\Python\Python313\Lib\site-packages\fastapi\__init__.py", line 7, in <module>
    from .applications import FastAPI as FastAPI
  File "C:\Users\eye43\AppData\Local\Programs\Python\Python313\Lib\site-packages\fastapi\applications.py", line 16, in <module>
    from fastapi import routing
  File "C:\Users\eye43\AppData\Local\Programs\Python\Python313\Lib\site-packages\fastapi\routing.py", line 24, in <module>
    from fastapi.dependencies.models import Dependant
  File "C:\Users\eye43\AppData\Local\Programs\Python\Python313\Lib\site-packages\fastapi\dependencies\models.py", line 3, in <module>
    from fastapi.security.base import SecurityBase
  File "C:\Users\eye43\AppData\Local\Programs\Python\Python313\Lib\site-packages\fastapi\security\__init__.py", line 1, in <module>
    from .api_key import APIKeyCookie as APIKeyCookie
  File "C:\Users\eye43\AppData\Local\Programs\Python\Python313\Lib\site-packages\fastapi\security\api_key.py", line 3, in <module>
    from fastapi.openapi.models import APIKey, APIKeyIn
  File "C:\Users\eye43\AppData\Local\Programs\Python\Python313\Lib\site-packages\fastapi\openapi\models.py", line 103, in <module>
    class Schema(BaseModel):
    ...<38 lines>...
            extra: str = "allow"
  File "C:\Users\eye43\AppData\Local\Programs\Python\Python313\Lib\site-packages\pydantic\main.py", line 286, in __new__
    cls.__try_update_forward_refs__()
    ~~~~~~~~~~~~~~~~~~~~~~~~~~~~~~~^^
  File "C:\Users\eye43\AppData\Local\Programs\Python\Python313\Lib\site-packages\pydantic\main.py", line 808, in __try_update_forward_refs__
    update_model_forward_refs(cls, cls.__fields__.values(), cls.__config__.json_encoders, localns, (NameError,))
    ~~~~~~~~~~~~~~~~~~~~~~~~~^^^^^^^^^^^^^^^^^^^^^^^^^^^^^^^^^^^^^^^^^^^^^^^^^^^^^^^^^^^^^^^^^^^^^^^^^^^^^^^^^^^
  File "C:\Users\eye43\AppData\Local\Programs\Python\Python313\Lib\site-packages\pydantic\typing.py", line 554, in update_model_forward_refs
    update_field_forward_refs(f, globalns=globalns, localns=localns)
    ~~~~~~~~~~~~~~~~~~~~~~~~~^^^^^^^^^^^^^^^^^^^^^^^^^^^^^^^^^^^^^^^
  File "C:\Users\eye43\AppData\Local\Programs\Python\Python313\Lib\site-packages\pydantic\typing.py", line 520, in update_field_forward_refs
    field.type_ = evaluate_forwardref(field.type_, globalns, localns or None)
                  ~~~~~~~~~~~~~~~~~~~^^^^^^^^^^^^^^^^^^^^^^^^^^^^^^^^^^^^^^^^
  File "C:\Users\eye43\AppData\Local\Programs\Python\Python313\Lib\site-packages\pydantic\typing.py", line 66, in evaluate_forwardref
    return cast(Any, type_)._evaluate(globalns, localns, set())
           ~~~~~~~~~~~~~~~~~~~~~~~~~~^^^^^^^^^^^^^^^^^^^^^^^^^^
TypeError: ForwardRef._evaluate() missing 1 required keyword-only argument: 'recursive_guard'
  - Captured at: 2025-10-13T17:00:21.611287+00:00
  - Suggested action: Investigate
  - Stderr preview:
    > Traceback (most recent call last):
    >   File "<frozen runpy>", line 198, in _run_module_as_main
    >   File "<frozen runpy>", line 88, in _run_code
    >   File "C:\Users\eye43\AppData\Local\Programs\Python\Python313\Lib\site-packages\pyright\__main__.py", line 1, in <module>
    >     from fastapi.cli import main
    > …

- [ ] `x_make_github_clones_x` · `ruff_fix` — ruff_fix failed for x_make_github_clones_x (exit 1) cwd: C:\x_runner_x\x_make_github_clones_x command: C:\Users\eye43\AppData\Local\Programs\Python\Python313\python.exe -m ruff check . --fix --select ALL --ignore D,COM812,ISC001,T20 --line…
  - Command: `C:\Users\eye43\AppData\Local\Programs\Python\Python313\python.exe -m ruff check . --fix --select ALL --ignore D,COM812,ISC001,T20 --line-length 88 --target-version py311`
  - Exit: exit 1
  - Repo path: `C:\x_runner_x\x_make_github_clones_x`
  - Tool version: ruff 0.14.0
  - Captured at: 2025-10-13T17:00:21.956187+00:00
  - Suggested action: Investigate
  - Stdout preview:
    > TC003 Move standard library import `collections.abc.Callable` into a type-checking block
    >   --> x_cls_make_github_clones_x.py:19:29
    >    |
    > 17 | import time
    > 18 | import urllib.request
    > …

- [ ] `x_make_github_clones_x` · `ruff_check` — ruff_check failed for x_make_github_clones_x (exit 1) cwd: C:\x_runner_x\x_make_github_clones_x command: C:\Users\eye43\AppData\Local\Programs\Python\Python313\python.exe -m ruff check . --select ALL --ignore D,COM812,ISC001,T20 --line-len…
  - Command: `C:\Users\eye43\AppData\Local\Programs\Python\Python313\python.exe -m ruff check . --select ALL --ignore D,COM812,ISC001,T20 --line-length 88 --target-version py311`
  - Exit: exit 1
  - Repo path: `C:\x_runner_x\x_make_github_clones_x`
  - Tool version: ruff 0.14.0
  - Captured at: 2025-10-13T17:00:23.442456+00:00
  - Suggested action: Investigate
  - Stdout preview:
    > TC003 Move standard library import `collections.abc.Callable` into a type-checking block
    >   --> x_cls_make_github_clones_x.py:19:29
    >    |
    > 17 | import time
    > 18 | import urllib.request
    > …

- [ ] `x_make_github_clones_x` · `mypy` — mypy failed for x_make_github_clones_x (exit 1) cwd: C:\x_runner_x\x_make_github_clones_x command: C:\Users\eye43\AppData\Local\Programs\Python\Python313\python.exe -m mypy . --strict --no-warn-unused-configs --show-error-codes --warn-retu…
  - Command: `C:\Users\eye43\AppData\Local\Programs\Python\Python313\python.exe -m mypy . --strict --no-warn-unused-configs --show-error-codes --warn-return-any --warn-unreachable --disallow-any-unimported --disallow-any-expr --disallow-any-decorated --disallow-any-explicit`
  - Exit: exit 1
  - Repo path: `C:\x_runner_x\x_make_github_clones_x`
  - Tool version: mypy 3.4.3 (compiled: yes)
  - Captured at: 2025-10-13T17:00:24.371954+00:00
  - Suggested action: Investigate
  - Stdout preview:
    > x_cls_make_github_clones_x.py:608: error: Explicit "Any" is not allowed  [explicit-any]
    > x_cls_make_github_clones_x.py:619: error: "object" has no attribute "force_reclone"  [attr-defined]
    > x_cls_make_github_clones_x.py:663: error: Expression type contains "Any" (has type "Callable[..., object] | None")  [misc]
    > x_cls_make_github_clones_x.py:664: error: Expression type contains "Any" (has type "Callable[..., object] | None")  [misc]
    > x_cls_make_github_clones_x.py:676: error: Expression type contains "Any" (has type "Callable[..., object] | None")  [misc]
    > …

- [ ] `x_make_github_clones_x` · `pyright` — pyright failed for x_make_github_clones_x (exit 1) cwd: C:\x_runner_x\x_make_github_clones_x command: C:\Users\eye43\AppData\Local\Programs\Python\Python313\python.exe -m pyright . --level error started_at: 2025-10-13T17:00:24.372547+00:00…
  - Command: `C:\Users\eye43\AppData\Local\Programs\Python\Python313\python.exe -m pyright . --level error`
  - Exit: exit 1
  - Repo path: `C:\x_runner_x\x_make_github_clones_x`
  - Tool version: <exit 1> Traceback (most recent call last):
  File "<frozen runpy>", line 198, in _run_module_as_main
  File "<frozen runpy>", line 88, in _run_code
  File "C:\Users\eye43\AppData\Local\Programs\Python\Python313\Lib\site-packages\pyright\__main__.py", line 1, in <module>
    from fastapi.cli import main
  File "C:\Users\eye43\AppData\Local\Programs\Python\Python313\Lib\site-packages\fastapi\__init__.py", line 7, in <module>
    from .applications import FastAPI as FastAPI
  File "C:\Users\eye43\AppData\Local\Programs\Python\Python313\Lib\site-packages\fastapi\applications.py", line 16, in <module>
    from fastapi import routing
  File "C:\Users\eye43\AppData\Local\Programs\Python\Python313\Lib\site-packages\fastapi\routing.py", line 24, in <module>
    from fastapi.dependencies.models import Dependant
  File "C:\Users\eye43\AppData\Local\Programs\Python\Python313\Lib\site-packages\fastapi\dependencies\models.py", line 3, in <module>
    from fastapi.security.base import SecurityBase
  File "C:\Users\eye43\AppData\Local\Programs\Python\Python313\Lib\site-packages\fastapi\security\__init__.py", line 1, in <module>
    from .api_key import APIKeyCookie as APIKeyCookie
  File "C:\Users\eye43\AppData\Local\Programs\Python\Python313\Lib\site-packages\fastapi\security\api_key.py", line 3, in <module>
    from fastapi.openapi.models import APIKey, APIKeyIn
  File "C:\Users\eye43\AppData\Local\Programs\Python\Python313\Lib\site-packages\fastapi\openapi\models.py", line 103, in <module>
    class Schema(BaseModel):
    ...<38 lines>...
            extra: str = "allow"
  File "C:\Users\eye43\AppData\Local\Programs\Python\Python313\Lib\site-packages\pydantic\main.py", line 286, in __new__
    cls.__try_update_forward_refs__()
    ~~~~~~~~~~~~~~~~~~~~~~~~~~~~~~~^^
  File "C:\Users\eye43\AppData\Local\Programs\Python\Python313\Lib\site-packages\pydantic\main.py", line 808, in __try_update_forward_refs__
    update_model_forward_refs(cls, cls.__fields__.values(), cls.__config__.json_encoders, localns, (NameError,))
    ~~~~~~~~~~~~~~~~~~~~~~~~~^^^^^^^^^^^^^^^^^^^^^^^^^^^^^^^^^^^^^^^^^^^^^^^^^^^^^^^^^^^^^^^^^^^^^^^^^^^^^^^^^^^
  File "C:\Users\eye43\AppData\Local\Programs\Python\Python313\Lib\site-packages\pydantic\typing.py", line 554, in update_model_forward_refs
    update_field_forward_refs(f, globalns=globalns, localns=localns)
    ~~~~~~~~~~~~~~~~~~~~~~~~~^^^^^^^^^^^^^^^^^^^^^^^^^^^^^^^^^^^^^^^
  File "C:\Users\eye43\AppData\Local\Programs\Python\Python313\Lib\site-packages\pydantic\typing.py", line 520, in update_field_forward_refs
    field.type_ = evaluate_forwardref(field.type_, globalns, localns or None)
                  ~~~~~~~~~~~~~~~~~~~^^^^^^^^^^^^^^^^^^^^^^^^^^^^^^^^^^^^^^^^
  File "C:\Users\eye43\AppData\Local\Programs\Python\Python313\Lib\site-packages\pydantic\typing.py", line 66, in evaluate_forwardref
    return cast(Any, type_)._evaluate(globalns, localns, set())
           ~~~~~~~~~~~~~~~~~~~~~~~~~~^^^^^^^^^^^^^^^^^^^^^^^^^^
TypeError: ForwardRef._evaluate() missing 1 required keyword-only argument: 'recursive_guard'
  - Captured at: 2025-10-13T17:00:26.207207+00:00
  - Suggested action: Investigate
  - Stdout preview:
    > c:\x_runner_x\x_make_github_clones_x\x_cls_make_github_clones_x.py
    >   c:\x_runner_x\x_make_github_clones_x\x_cls_make_github_clones_x.py:619:16 - error: Cannot assign to attribute "force_reclone" for class "object"
    >   Â Â Attribute "force_reclone" is unknown (reportAttributeAccessIssue)
    > 1 error, 0 warnings, 0 informations

- [ ] `x_make_github_visitor_x` · `ruff_fix` — ruff_fix failed for x_make_github_visitor_x (exit 1) cwd: C:\x_runner_x\x_make_github_visitor_x command: C:\Users\eye43\AppData\Local\Programs\Python\Python313\python.exe -m ruff check . --fix --select ALL --ignore D,COM812,ISC001,T20 --li…
  - Command: `C:\Users\eye43\AppData\Local\Programs\Python\Python313\python.exe -m ruff check . --fix --select ALL --ignore D,COM812,ISC001,T20 --line-length 88 --target-version py311`
  - Exit: exit 1
  - Repo path: `C:\x_runner_x\x_make_github_visitor_x`
  - Tool version: ruff 0.14.0
  - Captured at: 2025-10-13T17:00:26.738365+00:00
  - Suggested action: Investigate
  - Stdout preview:
    > TC003 Move standard library import `collections.abc.Callable` into a type-checking block
    >  --> inspection_flow.py:5:29
    >   |
    > 3 | import importlib
    > 4 | import os
    > …

- [ ] `x_make_github_visitor_x` · `black` — black failed for x_make_github_visitor_x (exit 1) cwd: C:\x_runner_x\x_make_github_visitor_x command: C:\Users\eye43\AppData\Local\Programs\Python\Python313\python.exe -m black . --line-length 88 --target-version py311 --check --diff start…
  - Command: `C:\Users\eye43\AppData\Local\Programs\Python\Python313\python.exe -m black . --line-length 88 --target-version py311 --check --diff`
  - Exit: exit 1
  - Repo path: `C:\x_runner_x\x_make_github_visitor_x`
  - Tool version: python -m black, 25.9.0 (compiled: yes)
Python (CPython) 3.13.7
  - Captured at: 2025-10-13T17:00:28.802265+00:00
  - Suggested action: Investigate
  - Stdout preview:
    > --- C:\x_runner_x\x_make_github_visitor_x\inspection_flow.py	2025-10-13 14:49:15.838704+00:00
    > +++ C:\x_runner_x\x_make_github_visitor_x\inspection_flow.py	2025-10-13 17:00:27.487770+00:00
    > @@ -13,11 +13,13 @@
    >  class VisitorProtocol(Protocol):
    >      def run_inspect_flow(self) -> None: ...
    > …
  - Stderr preview:
    > would reformat C:\x_runner_x\x_make_github_visitor_x\inspection_flow.py
    > would reformat C:\x_runner_x\x_make_github_visitor_x\x_cls_make_github_visitor_x.py
    > 
    > Oh no! \U0001f4a5 \U0001f494 \U0001f4a5
    > 2 files would be reformatted, 3 files would be left unchanged.

- [ ] `x_make_github_visitor_x` · `ruff_check` — ruff_check failed for x_make_github_visitor_x (exit 1) cwd: C:\x_runner_x\x_make_github_visitor_x command: C:\Users\eye43\AppData\Local\Programs\Python\Python313\python.exe -m ruff check . --select ALL --ignore D,COM812,ISC001,T20 --line-l…
  - Command: `C:\Users\eye43\AppData\Local\Programs\Python\Python313\python.exe -m ruff check . --select ALL --ignore D,COM812,ISC001,T20 --line-length 88 --target-version py311`
  - Exit: exit 1
  - Repo path: `C:\x_runner_x\x_make_github_visitor_x`
  - Tool version: ruff 0.14.0
  - Captured at: 2025-10-13T17:00:28.910972+00:00
  - Suggested action: Investigate
  - Stdout preview:
    > TC003 Move standard library import `collections.abc.Callable` into a type-checking block
    >  --> inspection_flow.py:5:29
    >   |
    > 3 | import importlib
    > 4 | import os
    > …

- [ ] `x_make_github_visitor_x` · `mypy` — mypy failed for x_make_github_visitor_x (exit 1) cwd: C:\x_runner_x\x_make_github_visitor_x command: C:\Users\eye43\AppData\Local\Programs\Python\Python313\python.exe -m mypy . --strict --no-warn-unused-configs --show-error-codes --warn-re…
  - Command: `C:\Users\eye43\AppData\Local\Programs\Python\Python313\python.exe -m mypy . --strict --no-warn-unused-configs --show-error-codes --warn-return-any --warn-unreachable --disallow-any-unimported --disallow-any-expr --disallow-any-decorated --disallow-any-explicit`
  - Exit: exit 1
  - Repo path: `C:\x_runner_x\x_make_github_visitor_x`
  - Tool version: mypy 3.4.3 (compiled: yes)
  - Captured at: 2025-10-13T17:00:31.974646+00:00
  - Suggested action: Investigate
  - Stdout preview:
    > inspection_flow.py:10: error: Cannot find implementation or library stub for module named "x_make_common_x"  [import-not-found]
    > inspection_flow.py:10: note: See https://mypy.readthedocs.io/en/stable/running_mypy.html#missing-imports
    > inspection_flow.py:34: error: Expression type contains "Any" (has type "Any | None")  [misc]
    > inspection_flow.py:35: error: Expression type contains "Any" (has type "Any | None")  [misc]
    > inspection_flow.py:41: error: Expression type contains "Any" (has type "Any | None")  [misc]
    > …

- [ ] `x_make_github_visitor_x` · `pyright` — pyright failed for x_make_github_visitor_x (exit 1) cwd: C:\x_runner_x\x_make_github_visitor_x command: C:\Users\eye43\AppData\Local\Programs\Python\Python313\python.exe -m pyright . --level error started_at: 2025-10-13T17:00:31.975175+00:…
  - Command: `C:\Users\eye43\AppData\Local\Programs\Python\Python313\python.exe -m pyright . --level error`
  - Exit: exit 1
  - Repo path: `C:\x_runner_x\x_make_github_visitor_x`
  - Tool version: <exit 1> Traceback (most recent call last):
  File "<frozen runpy>", line 198, in _run_module_as_main
  File "<frozen runpy>", line 88, in _run_code
  File "C:\Users\eye43\AppData\Local\Programs\Python\Python313\Lib\site-packages\pyright\__main__.py", line 1, in <module>
    from fastapi.cli import main
  File "C:\Users\eye43\AppData\Local\Programs\Python\Python313\Lib\site-packages\fastapi\__init__.py", line 7, in <module>
    from .applications import FastAPI as FastAPI
  File "C:\Users\eye43\AppData\Local\Programs\Python\Python313\Lib\site-packages\fastapi\applications.py", line 16, in <module>
    from fastapi import routing
  File "C:\Users\eye43\AppData\Local\Programs\Python\Python313\Lib\site-packages\fastapi\routing.py", line 24, in <module>
    from fastapi.dependencies.models import Dependant
  File "C:\Users\eye43\AppData\Local\Programs\Python\Python313\Lib\site-packages\fastapi\dependencies\models.py", line 3, in <module>
    from fastapi.security.base import SecurityBase
  File "C:\Users\eye43\AppData\Local\Programs\Python\Python313\Lib\site-packages\fastapi\security\__init__.py", line 1, in <module>
    from .api_key import APIKeyCookie as APIKeyCookie
  File "C:\Users\eye43\AppData\Local\Programs\Python\Python313\Lib\site-packages\fastapi\security\api_key.py", line 3, in <module>
    from fastapi.openapi.models import APIKey, APIKeyIn
  File "C:\Users\eye43\AppData\Local\Programs\Python\Python313\Lib\site-packages\fastapi\openapi\models.py", line 103, in <module>
    class Schema(BaseModel):
    ...<38 lines>...
            extra: str = "allow"
  File "C:\Users\eye43\AppData\Local\Programs\Python\Python313\Lib\site-packages\pydantic\main.py", line 286, in __new__
    cls.__try_update_forward_refs__()
    ~~~~~~~~~~~~~~~~~~~~~~~~~~~~~~~^^
  File "C:\Users\eye43\AppData\Local\Programs\Python\Python313\Lib\site-packages\pydantic\main.py", line 808, in __try_update_forward_refs__
    update_model_forward_refs(cls, cls.__fields__.values(), cls.__config__.json_encoders, localns, (NameError,))
    ~~~~~~~~~~~~~~~~~~~~~~~~~^^^^^^^^^^^^^^^^^^^^^^^^^^^^^^^^^^^^^^^^^^^^^^^^^^^^^^^^^^^^^^^^^^^^^^^^^^^^^^^^^^^
  File "C:\Users\eye43\AppData\Local\Programs\Python\Python313\Lib\site-packages\pydantic\typing.py", line 554, in update_model_forward_refs
    update_field_forward_refs(f, globalns=globalns, localns=localns)
    ~~~~~~~~~~~~~~~~~~~~~~~~~^^^^^^^^^^^^^^^^^^^^^^^^^^^^^^^^^^^^^^^
  File "C:\Users\eye43\AppData\Local\Programs\Python\Python313\Lib\site-packages\pydantic\typing.py", line 520, in update_field_forward_refs
    field.type_ = evaluate_forwardref(field.type_, globalns, localns or None)
                  ~~~~~~~~~~~~~~~~~~~^^^^^^^^^^^^^^^^^^^^^^^^^^^^^^^^^^^^^^^^
  File "C:\Users\eye43\AppData\Local\Programs\Python\Python313\Lib\site-packages\pydantic\typing.py", line 66, in evaluate_forwardref
    return cast(Any, type_)._evaluate(globalns, localns, set())
           ~~~~~~~~~~~~~~~~~~~~~~~~~~^^^^^^^^^^^^^^^^^^^^^^^^^^
TypeError: ForwardRef._evaluate() missing 1 required keyword-only argument: 'recursive_guard'
  - Captured at: 2025-10-13T17:00:32.259378+00:00
  - Suggested action: Investigate
  - Stderr preview:
    > Traceback (most recent call last):
    >   File "<frozen runpy>", line 198, in _run_module_as_main
    >   File "<frozen runpy>", line 88, in _run_code
    >   File "C:\Users\eye43\AppData\Local\Programs\Python\Python313\Lib\site-packages\pyright\__main__.py", line 1, in <module>
    >     from fastapi.cli import main
    > …

- [ ] `x_make_graphviz_x` · `pyright` — pyright failed for x_make_graphviz_x (exit 1) cwd: C:\x_runner_x\x_make_graphviz_x command: C:\Users\eye43\AppData\Local\Programs\Python\Python313\python.exe -m pyright . --level error started_at: 2025-10-13T17:00:39.786329+00:00 duration:…
  - Command: `C:\Users\eye43\AppData\Local\Programs\Python\Python313\python.exe -m pyright . --level error`
  - Exit: exit 1
  - Repo path: `C:\x_runner_x\x_make_graphviz_x`
  - Tool version: <exit 1> Traceback (most recent call last):
  File "<frozen runpy>", line 198, in _run_module_as_main
  File "<frozen runpy>", line 88, in _run_code
  File "C:\Users\eye43\AppData\Local\Programs\Python\Python313\Lib\site-packages\pyright\__main__.py", line 1, in <module>
    from fastapi.cli import main
  File "C:\Users\eye43\AppData\Local\Programs\Python\Python313\Lib\site-packages\fastapi\__init__.py", line 7, in <module>
    from .applications import FastAPI as FastAPI
  File "C:\Users\eye43\AppData\Local\Programs\Python\Python313\Lib\site-packages\fastapi\applications.py", line 16, in <module>
    from fastapi import routing
  File "C:\Users\eye43\AppData\Local\Programs\Python\Python313\Lib\site-packages\fastapi\routing.py", line 24, in <module>
    from fastapi.dependencies.models import Dependant
  File "C:\Users\eye43\AppData\Local\Programs\Python\Python313\Lib\site-packages\fastapi\dependencies\models.py", line 3, in <module>
    from fastapi.security.base import SecurityBase
  File "C:\Users\eye43\AppData\Local\Programs\Python\Python313\Lib\site-packages\fastapi\security\__init__.py", line 1, in <module>
    from .api_key import APIKeyCookie as APIKeyCookie
  File "C:\Users\eye43\AppData\Local\Programs\Python\Python313\Lib\site-packages\fastapi\security\api_key.py", line 3, in <module>
    from fastapi.openapi.models import APIKey, APIKeyIn
  File "C:\Users\eye43\AppData\Local\Programs\Python\Python313\Lib\site-packages\fastapi\openapi\models.py", line 103, in <module>
    class Schema(BaseModel):
    ...<38 lines>...
            extra: str = "allow"
  File "C:\Users\eye43\AppData\Local\Programs\Python\Python313\Lib\site-packages\pydantic\main.py", line 286, in __new__
    cls.__try_update_forward_refs__()
    ~~~~~~~~~~~~~~~~~~~~~~~~~~~~~~~^^
  File "C:\Users\eye43\AppData\Local\Programs\Python\Python313\Lib\site-packages\pydantic\main.py", line 808, in __try_update_forward_refs__
    update_model_forward_refs(cls, cls.__fields__.values(), cls.__config__.json_encoders, localns, (NameError,))
    ~~~~~~~~~~~~~~~~~~~~~~~~~^^^^^^^^^^^^^^^^^^^^^^^^^^^^^^^^^^^^^^^^^^^^^^^^^^^^^^^^^^^^^^^^^^^^^^^^^^^^^^^^^^^
  File "C:\Users\eye43\AppData\Local\Programs\Python\Python313\Lib\site-packages\pydantic\typing.py", line 554, in update_model_forward_refs
    update_field_forward_refs(f, globalns=globalns, localns=localns)
    ~~~~~~~~~~~~~~~~~~~~~~~~~^^^^^^^^^^^^^^^^^^^^^^^^^^^^^^^^^^^^^^^
  File "C:\Users\eye43\AppData\Local\Programs\Python\Python313\Lib\site-packages\pydantic\typing.py", line 520, in update_field_forward_refs
    field.type_ = evaluate_forwardref(field.type_, globalns, localns or None)
                  ~~~~~~~~~~~~~~~~~~~^^^^^^^^^^^^^^^^^^^^^^^^^^^^^^^^^^^^^^^^
  File "C:\Users\eye43\AppData\Local\Programs\Python\Python313\Lib\site-packages\pydantic\typing.py", line 66, in evaluate_forwardref
    return cast(Any, type_)._evaluate(globalns, localns, set())
           ~~~~~~~~~~~~~~~~~~~~~~~~~~^^^^^^^^^^^^^^^^^^^^^^^^^^
TypeError: ForwardRef._evaluate() missing 1 required keyword-only argument: 'recursive_guard'
  - Captured at: 2025-10-13T17:00:40.354960+00:00
  - Suggested action: Investigate
  - Stderr preview:
    > Traceback (most recent call last):
    >   File "<frozen runpy>", line 198, in _run_module_as_main
    >   File "<frozen runpy>", line 88, in _run_code
    >   File "C:\Users\eye43\AppData\Local\Programs\Python\Python313\Lib\site-packages\pyright\__main__.py", line 1, in <module>
    >     from fastapi.cli import main
    > …

- [ ] `x_make_markdown_x` · `pyright` — pyright failed for x_make_markdown_x (exit 1) cwd: C:\x_runner_x\x_make_markdown_x command: C:\Users\eye43\AppData\Local\Programs\Python\Python313\python.exe -m pyright . --level error started_at: 2025-10-13T17:00:50.409352+00:00 duration:…
  - Command: `C:\Users\eye43\AppData\Local\Programs\Python\Python313\python.exe -m pyright . --level error`
  - Exit: exit 1
  - Repo path: `C:\x_runner_x\x_make_markdown_x`
  - Tool version: <exit 1> Traceback (most recent call last):
  File "<frozen runpy>", line 198, in _run_module_as_main
  File "<frozen runpy>", line 88, in _run_code
  File "C:\Users\eye43\AppData\Local\Programs\Python\Python313\Lib\site-packages\pyright\__main__.py", line 1, in <module>
    from fastapi.cli import main
  File "C:\Users\eye43\AppData\Local\Programs\Python\Python313\Lib\site-packages\fastapi\__init__.py", line 7, in <module>
    from .applications import FastAPI as FastAPI
  File "C:\Users\eye43\AppData\Local\Programs\Python\Python313\Lib\site-packages\fastapi\applications.py", line 16, in <module>
    from fastapi import routing
  File "C:\Users\eye43\AppData\Local\Programs\Python\Python313\Lib\site-packages\fastapi\routing.py", line 24, in <module>
    from fastapi.dependencies.models import Dependant
  File "C:\Users\eye43\AppData\Local\Programs\Python\Python313\Lib\site-packages\fastapi\dependencies\models.py", line 3, in <module>
    from fastapi.security.base import SecurityBase
  File "C:\Users\eye43\AppData\Local\Programs\Python\Python313\Lib\site-packages\fastapi\security\__init__.py", line 1, in <module>
    from .api_key import APIKeyCookie as APIKeyCookie
  File "C:\Users\eye43\AppData\Local\Programs\Python\Python313\Lib\site-packages\fastapi\security\api_key.py", line 3, in <module>
    from fastapi.openapi.models import APIKey, APIKeyIn
  File "C:\Users\eye43\AppData\Local\Programs\Python\Python313\Lib\site-packages\fastapi\openapi\models.py", line 103, in <module>
    class Schema(BaseModel):
    ...<38 lines>...
            extra: str = "allow"
  File "C:\Users\eye43\AppData\Local\Programs\Python\Python313\Lib\site-packages\pydantic\main.py", line 286, in __new__
    cls.__try_update_forward_refs__()
    ~~~~~~~~~~~~~~~~~~~~~~~~~~~~~~~^^
  File "C:\Users\eye43\AppData\Local\Programs\Python\Python313\Lib\site-packages\pydantic\main.py", line 808, in __try_update_forward_refs__
    update_model_forward_refs(cls, cls.__fields__.values(), cls.__config__.json_encoders, localns, (NameError,))
    ~~~~~~~~~~~~~~~~~~~~~~~~~^^^^^^^^^^^^^^^^^^^^^^^^^^^^^^^^^^^^^^^^^^^^^^^^^^^^^^^^^^^^^^^^^^^^^^^^^^^^^^^^^^^
  File "C:\Users\eye43\AppData\Local\Programs\Python\Python313\Lib\site-packages\pydantic\typing.py", line 554, in update_model_forward_refs
    update_field_forward_refs(f, globalns=globalns, localns=localns)
    ~~~~~~~~~~~~~~~~~~~~~~~~~^^^^^^^^^^^^^^^^^^^^^^^^^^^^^^^^^^^^^^^
  File "C:\Users\eye43\AppData\Local\Programs\Python\Python313\Lib\site-packages\pydantic\typing.py", line 520, in update_field_forward_refs
    field.type_ = evaluate_forwardref(field.type_, globalns, localns or None)
                  ~~~~~~~~~~~~~~~~~~~^^^^^^^^^^^^^^^^^^^^^^^^^^^^^^^^^^^^^^^^
  File "C:\Users\eye43\AppData\Local\Programs\Python\Python313\Lib\site-packages\pydantic\typing.py", line 66, in evaluate_forwardref
    return cast(Any, type_)._evaluate(globalns, localns, set())
           ~~~~~~~~~~~~~~~~~~~~~~~~~~^^^^^^^^^^^^^^^^^^^^^^^^^^
TypeError: ForwardRef._evaluate() missing 1 required keyword-only argument: 'recursive_guard'
  - Captured at: 2025-10-13T17:00:50.679716+00:00
  - Suggested action: Investigate
  - Stderr preview:
    > Traceback (most recent call last):
    >   File "<frozen runpy>", line 198, in _run_module_as_main
    >   File "<frozen runpy>", line 88, in _run_code
    >   File "C:\Users\eye43\AppData\Local\Programs\Python\Python313\Lib\site-packages\pyright\__main__.py", line 1, in <module>
    >     from fastapi.cli import main
    > …

- [ ] `x_make_mermaid_x` · `pyright` — pyright failed for x_make_mermaid_x (exit 1) cwd: C:\x_runner_x\x_make_mermaid_x command: C:\Users\eye43\AppData\Local\Programs\Python\Python313\python.exe -m pyright . --level error started_at: 2025-10-13T17:00:58.179230+00:00 duration: 0…
  - Command: `C:\Users\eye43\AppData\Local\Programs\Python\Python313\python.exe -m pyright . --level error`
  - Exit: exit 1
  - Repo path: `C:\x_runner_x\x_make_mermaid_x`
  - Tool version: <exit 1> Traceback (most recent call last):
  File "<frozen runpy>", line 198, in _run_module_as_main
  File "<frozen runpy>", line 88, in _run_code
  File "C:\Users\eye43\AppData\Local\Programs\Python\Python313\Lib\site-packages\pyright\__main__.py", line 1, in <module>
    from fastapi.cli import main
  File "C:\Users\eye43\AppData\Local\Programs\Python\Python313\Lib\site-packages\fastapi\__init__.py", line 7, in <module>
    from .applications import FastAPI as FastAPI
  File "C:\Users\eye43\AppData\Local\Programs\Python\Python313\Lib\site-packages\fastapi\applications.py", line 16, in <module>
    from fastapi import routing
  File "C:\Users\eye43\AppData\Local\Programs\Python\Python313\Lib\site-packages\fastapi\routing.py", line 24, in <module>
    from fastapi.dependencies.models import Dependant
  File "C:\Users\eye43\AppData\Local\Programs\Python\Python313\Lib\site-packages\fastapi\dependencies\models.py", line 3, in <module>
    from fastapi.security.base import SecurityBase
  File "C:\Users\eye43\AppData\Local\Programs\Python\Python313\Lib\site-packages\fastapi\security\__init__.py", line 1, in <module>
    from .api_key import APIKeyCookie as APIKeyCookie
  File "C:\Users\eye43\AppData\Local\Programs\Python\Python313\Lib\site-packages\fastapi\security\api_key.py", line 3, in <module>
    from fastapi.openapi.models import APIKey, APIKeyIn
  File "C:\Users\eye43\AppData\Local\Programs\Python\Python313\Lib\site-packages\fastapi\openapi\models.py", line 103, in <module>
    class Schema(BaseModel):
    ...<38 lines>...
            extra: str = "allow"
  File "C:\Users\eye43\AppData\Local\Programs\Python\Python313\Lib\site-packages\pydantic\main.py", line 286, in __new__
    cls.__try_update_forward_refs__()
    ~~~~~~~~~~~~~~~~~~~~~~~~~~~~~~~^^
  File "C:\Users\eye43\AppData\Local\Programs\Python\Python313\Lib\site-packages\pydantic\main.py", line 808, in __try_update_forward_refs__
    update_model_forward_refs(cls, cls.__fields__.values(), cls.__config__.json_encoders, localns, (NameError,))
    ~~~~~~~~~~~~~~~~~~~~~~~~~^^^^^^^^^^^^^^^^^^^^^^^^^^^^^^^^^^^^^^^^^^^^^^^^^^^^^^^^^^^^^^^^^^^^^^^^^^^^^^^^^^^
  File "C:\Users\eye43\AppData\Local\Programs\Python\Python313\Lib\site-packages\pydantic\typing.py", line 554, in update_model_forward_refs
    update_field_forward_refs(f, globalns=globalns, localns=localns)
    ~~~~~~~~~~~~~~~~~~~~~~~~~^^^^^^^^^^^^^^^^^^^^^^^^^^^^^^^^^^^^^^^
  File "C:\Users\eye43\AppData\Local\Programs\Python\Python313\Lib\site-packages\pydantic\typing.py", line 520, in update_field_forward_refs
    field.type_ = evaluate_forwardref(field.type_, globalns, localns or None)
                  ~~~~~~~~~~~~~~~~~~~^^^^^^^^^^^^^^^^^^^^^^^^^^^^^^^^^^^^^^^^
  File "C:\Users\eye43\AppData\Local\Programs\Python\Python313\Lib\site-packages\pydantic\typing.py", line 66, in evaluate_forwardref
    return cast(Any, type_)._evaluate(globalns, localns, set())
           ~~~~~~~~~~~~~~~~~~~~~~~~~~^^^^^^^^^^^^^^^^^^^^^^^^^^
TypeError: ForwardRef._evaluate() missing 1 required keyword-only argument: 'recursive_guard'
  - Captured at: 2025-10-13T17:00:58.409156+00:00
  - Suggested action: Investigate
  - Stderr preview:
    > Traceback (most recent call last):
    >   File "<frozen runpy>", line 198, in _run_module_as_main
    >   File "<frozen runpy>", line 88, in _run_code
    >   File "C:\Users\eye43\AppData\Local\Programs\Python\Python313\Lib\site-packages\pyright\__main__.py", line 1, in <module>
    >     from fastapi.cli import main
    > …

- [ ] `x_make_persistent_env_var_x` · `pyright` — pyright failed for x_make_persistent_env_var_x (exit 1) cwd: C:\x_runner_x\x_make_persistent_env_var_x command: C:\Users\eye43\AppData\Local\Programs\Python\Python313\python.exe -m pyright . --level error started_at: 2025-10-13T17:01:01.85…
  - Command: `C:\Users\eye43\AppData\Local\Programs\Python\Python313\python.exe -m pyright . --level error`
  - Exit: exit 1
  - Repo path: `C:\x_runner_x\x_make_persistent_env_var_x`
  - Tool version: <exit 1> Traceback (most recent call last):
  File "<frozen runpy>", line 198, in _run_module_as_main
  File "<frozen runpy>", line 88, in _run_code
  File "C:\Users\eye43\AppData\Local\Programs\Python\Python313\Lib\site-packages\pyright\__main__.py", line 1, in <module>
    from fastapi.cli import main
  File "C:\Users\eye43\AppData\Local\Programs\Python\Python313\Lib\site-packages\fastapi\__init__.py", line 7, in <module>
    from .applications import FastAPI as FastAPI
  File "C:\Users\eye43\AppData\Local\Programs\Python\Python313\Lib\site-packages\fastapi\applications.py", line 16, in <module>
    from fastapi import routing
  File "C:\Users\eye43\AppData\Local\Programs\Python\Python313\Lib\site-packages\fastapi\routing.py", line 24, in <module>
    from fastapi.dependencies.models import Dependant
  File "C:\Users\eye43\AppData\Local\Programs\Python\Python313\Lib\site-packages\fastapi\dependencies\models.py", line 3, in <module>
    from fastapi.security.base import SecurityBase
  File "C:\Users\eye43\AppData\Local\Programs\Python\Python313\Lib\site-packages\fastapi\security\__init__.py", line 1, in <module>
    from .api_key import APIKeyCookie as APIKeyCookie
  File "C:\Users\eye43\AppData\Local\Programs\Python\Python313\Lib\site-packages\fastapi\security\api_key.py", line 3, in <module>
    from fastapi.openapi.models import APIKey, APIKeyIn
  File "C:\Users\eye43\AppData\Local\Programs\Python\Python313\Lib\site-packages\fastapi\openapi\models.py", line 103, in <module>
    class Schema(BaseModel):
    ...<38 lines>...
            extra: str = "allow"
  File "C:\Users\eye43\AppData\Local\Programs\Python\Python313\Lib\site-packages\pydantic\main.py", line 286, in __new__
    cls.__try_update_forward_refs__()
    ~~~~~~~~~~~~~~~~~~~~~~~~~~~~~~~^^
  File "C:\Users\eye43\AppData\Local\Programs\Python\Python313\Lib\site-packages\pydantic\main.py", line 808, in __try_update_forward_refs__
    update_model_forward_refs(cls, cls.__fields__.values(), cls.__config__.json_encoders, localns, (NameError,))
    ~~~~~~~~~~~~~~~~~~~~~~~~~^^^^^^^^^^^^^^^^^^^^^^^^^^^^^^^^^^^^^^^^^^^^^^^^^^^^^^^^^^^^^^^^^^^^^^^^^^^^^^^^^^^
  File "C:\Users\eye43\AppData\Local\Programs\Python\Python313\Lib\site-packages\pydantic\typing.py", line 554, in update_model_forward_refs
    update_field_forward_refs(f, globalns=globalns, localns=localns)
    ~~~~~~~~~~~~~~~~~~~~~~~~~^^^^^^^^^^^^^^^^^^^^^^^^^^^^^^^^^^^^^^^
  File "C:\Users\eye43\AppData\Local\Programs\Python\Python313\Lib\site-packages\pydantic\typing.py", line 520, in update_field_forward_refs
    field.type_ = evaluate_forwardref(field.type_, globalns, localns or None)
                  ~~~~~~~~~~~~~~~~~~~^^^^^^^^^^^^^^^^^^^^^^^^^^^^^^^^^^^^^^^^
  File "C:\Users\eye43\AppData\Local\Programs\Python\Python313\Lib\site-packages\pydantic\typing.py", line 66, in evaluate_forwardref
    return cast(Any, type_)._evaluate(globalns, localns, set())
           ~~~~~~~~~~~~~~~~~~~~~~~~~~^^^^^^^^^^^^^^^^^^^^^^^^^^
TypeError: ForwardRef._evaluate() missing 1 required keyword-only argument: 'recursive_guard'
  - Captured at: 2025-10-13T17:01:02.074729+00:00
  - Suggested action: Investigate
  - Stderr preview:
    > Traceback (most recent call last):
    >   File "<frozen runpy>", line 198, in _run_module_as_main
    >   File "<frozen runpy>", line 88, in _run_code
    >   File "C:\Users\eye43\AppData\Local\Programs\Python\Python313\Lib\site-packages\pyright\__main__.py", line 1, in <module>
    >     from fastapi.cli import main
    > …

- [ ] `x_make_pip_updates_x` · `ruff_fix` — ruff_fix failed for x_make_pip_updates_x (exit 1) cwd: C:\x_runner_x\x_make_pip_updates_x command: C:\Users\eye43\AppData\Local\Programs\Python\Python313\python.exe -m ruff check . --fix --select ALL --ignore D,COM812,ISC001,T20 --line-len…
  - Command: `C:\Users\eye43\AppData\Local\Programs\Python\Python313\python.exe -m ruff check . --fix --select ALL --ignore D,COM812,ISC001,T20 --line-length 88 --target-version py311`
  - Exit: exit 1
  - Repo path: `C:\x_runner_x\x_make_pip_updates_x`
  - Tool version: ruff 0.14.0
  - Captured at: 2025-10-13T17:01:02.991857+00:00
  - Suggested action: Investigate
  - Stdout preview:
    > TRY003 Avoid specifying long messages outside the exception class
    >    --> update_flow.py:115:11
    >     |
    > 113 |     if last_exc is not None:
    > 114 |         raise last_exc
    > …

- [ ] `x_make_pip_updates_x` · `black` — black failed for x_make_pip_updates_x (exit 1) cwd: C:\x_runner_x\x_make_pip_updates_x command: C:\Users\eye43\AppData\Local\Programs\Python\Python313\python.exe -m black . --line-length 88 --target-version py311 --check --diff started_at:…
  - Command: `C:\Users\eye43\AppData\Local\Programs\Python\Python313\python.exe -m black . --line-length 88 --target-version py311 --check --diff`
  - Exit: exit 1
  - Repo path: `C:\x_runner_x\x_make_pip_updates_x`
  - Tool version: python -m black, 25.9.0 (compiled: yes)
Python (CPython) 3.13.7
  - Captured at: 2025-10-13T17:01:04.032698+00:00
  - Suggested action: Investigate
  - Stdout preview:
    > --- C:\x_runner_x\x_make_pip_updates_x\update_flow.py	2025-10-13 17:01:02.972242+00:00
    > +++ C:\x_runner_x\x_make_pip_updates_x\update_flow.py	2025-10-13 17:01:03.869725+00:00
    > @@ -110,11 +110,13 @@
    >          except TypeError as exc:
    >              last_exc = exc
    > …
  - Stderr preview:
    > would reformat C:\x_runner_x\x_make_pip_updates_x\update_flow.py
    > 
    > Oh no! \U0001f4a5 \U0001f494 \U0001f4a5
    > 1 file would be reformatted, 4 files would be left unchanged.

- [ ] `x_make_pip_updates_x` · `ruff_check` — ruff_check failed for x_make_pip_updates_x (exit 1) cwd: C:\x_runner_x\x_make_pip_updates_x command: C:\Users\eye43\AppData\Local\Programs\Python\Python313\python.exe -m ruff check . --select ALL --ignore D,COM812,ISC001,T20 --line-length …
  - Command: `C:\Users\eye43\AppData\Local\Programs\Python\Python313\python.exe -m ruff check . --select ALL --ignore D,COM812,ISC001,T20 --line-length 88 --target-version py311`
  - Exit: exit 1
  - Repo path: `C:\x_runner_x\x_make_pip_updates_x`
  - Tool version: ruff 0.14.0
  - Captured at: 2025-10-13T17:01:04.160724+00:00
  - Suggested action: Investigate
  - Stdout preview:
    > TRY003 Avoid specifying long messages outside the exception class
    >    --> update_flow.py:115:11
    >     |
    > 113 |     if last_exc is not None:
    > 114 |         raise last_exc
    > …

- [ ] `x_make_pip_updates_x` · `mypy` — mypy failed for x_make_pip_updates_x (exit 1) cwd: C:\x_runner_x\x_make_pip_updates_x command: C:\Users\eye43\AppData\Local\Programs\Python\Python313\python.exe -m mypy . --strict --no-warn-unused-configs --show-error-codes --warn-return-a…
  - Command: `C:\Users\eye43\AppData\Local\Programs\Python\Python313\python.exe -m mypy . --strict --no-warn-unused-configs --show-error-codes --warn-return-any --warn-unreachable --disallow-any-unimported --disallow-any-expr --disallow-any-decorated --disallow-any-explicit`
  - Exit: exit 1
  - Repo path: `C:\x_runner_x\x_make_pip_updates_x`
  - Tool version: mypy 3.4.3 (compiled: yes)
  - Captured at: 2025-10-13T17:01:08.283149+00:00
  - Suggested action: Investigate
  - Stdout preview:
    > update_flow.py:19: error: Explicit "Any" is not allowed  [explicit-any]
    > update_flow.py:144: error: Unused "type: ignore" comment  [unused-ignore]
    > update_flow.py:256: error: Incompatible types in assignment (expression has type "Generator[tuple[str, None], None, None]", variable has type "ItemsView[str, str | None]")  [assignment]
    > Found 3 errors in 1 file (checked 5 source files)

- [ ] `x_make_pip_updates_x` · `pyright` — pyright failed for x_make_pip_updates_x (exit 1) cwd: C:\x_runner_x\x_make_pip_updates_x command: C:\Users\eye43\AppData\Local\Programs\Python\Python313\python.exe -m pyright . --level error started_at: 2025-10-13T17:01:08.283643+00:00 dur…
  - Command: `C:\Users\eye43\AppData\Local\Programs\Python\Python313\python.exe -m pyright . --level error`
  - Exit: exit 1
  - Repo path: `C:\x_runner_x\x_make_pip_updates_x`
  - Tool version: <exit 1> Traceback (most recent call last):
  File "<frozen runpy>", line 198, in _run_module_as_main
  File "<frozen runpy>", line 88, in _run_code
  File "C:\Users\eye43\AppData\Local\Programs\Python\Python313\Lib\site-packages\pyright\__main__.py", line 1, in <module>
    from fastapi.cli import main
  File "C:\Users\eye43\AppData\Local\Programs\Python\Python313\Lib\site-packages\fastapi\__init__.py", line 7, in <module>
    from .applications import FastAPI as FastAPI
  File "C:\Users\eye43\AppData\Local\Programs\Python\Python313\Lib\site-packages\fastapi\applications.py", line 16, in <module>
    from fastapi import routing
  File "C:\Users\eye43\AppData\Local\Programs\Python\Python313\Lib\site-packages\fastapi\routing.py", line 24, in <module>
    from fastapi.dependencies.models import Dependant
  File "C:\Users\eye43\AppData\Local\Programs\Python\Python313\Lib\site-packages\fastapi\dependencies\models.py", line 3, in <module>
    from fastapi.security.base import SecurityBase
  File "C:\Users\eye43\AppData\Local\Programs\Python\Python313\Lib\site-packages\fastapi\security\__init__.py", line 1, in <module>
    from .api_key import APIKeyCookie as APIKeyCookie
  File "C:\Users\eye43\AppData\Local\Programs\Python\Python313\Lib\site-packages\fastapi\security\api_key.py", line 3, in <module>
    from fastapi.openapi.models import APIKey, APIKeyIn
  File "C:\Users\eye43\AppData\Local\Programs\Python\Python313\Lib\site-packages\fastapi\openapi\models.py", line 103, in <module>
    class Schema(BaseModel):
    ...<38 lines>...
            extra: str = "allow"
  File "C:\Users\eye43\AppData\Local\Programs\Python\Python313\Lib\site-packages\pydantic\main.py", line 286, in __new__
    cls.__try_update_forward_refs__()
    ~~~~~~~~~~~~~~~~~~~~~~~~~~~~~~~^^
  File "C:\Users\eye43\AppData\Local\Programs\Python\Python313\Lib\site-packages\pydantic\main.py", line 808, in __try_update_forward_refs__
    update_model_forward_refs(cls, cls.__fields__.values(), cls.__config__.json_encoders, localns, (NameError,))
    ~~~~~~~~~~~~~~~~~~~~~~~~~^^^^^^^^^^^^^^^^^^^^^^^^^^^^^^^^^^^^^^^^^^^^^^^^^^^^^^^^^^^^^^^^^^^^^^^^^^^^^^^^^^^
  File "C:\Users\eye43\AppData\Local\Programs\Python\Python313\Lib\site-packages\pydantic\typing.py", line 554, in update_model_forward_refs
    update_field_forward_refs(f, globalns=globalns, localns=localns)
    ~~~~~~~~~~~~~~~~~~~~~~~~~^^^^^^^^^^^^^^^^^^^^^^^^^^^^^^^^^^^^^^^
  File "C:\Users\eye43\AppData\Local\Programs\Python\Python313\Lib\site-packages\pydantic\typing.py", line 520, in update_field_forward_refs
    field.type_ = evaluate_forwardref(field.type_, globalns, localns or None)
                  ~~~~~~~~~~~~~~~~~~~^^^^^^^^^^^^^^^^^^^^^^^^^^^^^^^^^^^^^^^^
  File "C:\Users\eye43\AppData\Local\Programs\Python\Python313\Lib\site-packages\pydantic\typing.py", line 66, in evaluate_forwardref
    return cast(Any, type_)._evaluate(globalns, localns, set())
           ~~~~~~~~~~~~~~~~~~~~~~~~~~^^^^^^^^^^^^^^^^^^^^^^^^^^
TypeError: ForwardRef._evaluate() missing 1 required keyword-only argument: 'recursive_guard'
  - Captured at: 2025-10-13T17:01:08.583280+00:00
  - Suggested action: Investigate
  - Stderr preview:
    > Traceback (most recent call last):
    >   File "<frozen runpy>", line 198, in _run_module_as_main
    >   File "<frozen runpy>", line 88, in _run_code
    >   File "C:\Users\eye43\AppData\Local\Programs\Python\Python313\Lib\site-packages\pyright\__main__.py", line 1, in <module>
    >     from fastapi.cli import main
    > …

- [ ] `x_make_py_mod_sideload_x` · `pyright` — pyright failed for x_make_py_mod_sideload_x (exit 1) cwd: C:\x_runner_x\x_make_py_mod_sideload_x command: C:\Users\eye43\AppData\Local\Programs\Python\Python313\python.exe -m pyright . --level error started_at: 2025-10-13T17:01:11.759172+0…
  - Command: `C:\Users\eye43\AppData\Local\Programs\Python\Python313\python.exe -m pyright . --level error`
  - Exit: exit 1
  - Repo path: `C:\x_runner_x\x_make_py_mod_sideload_x`
  - Tool version: <exit 1> Traceback (most recent call last):
  File "<frozen runpy>", line 198, in _run_module_as_main
  File "<frozen runpy>", line 88, in _run_code
  File "C:\Users\eye43\AppData\Local\Programs\Python\Python313\Lib\site-packages\pyright\__main__.py", line 1, in <module>
    from fastapi.cli import main
  File "C:\Users\eye43\AppData\Local\Programs\Python\Python313\Lib\site-packages\fastapi\__init__.py", line 7, in <module>
    from .applications import FastAPI as FastAPI
  File "C:\Users\eye43\AppData\Local\Programs\Python\Python313\Lib\site-packages\fastapi\applications.py", line 16, in <module>
    from fastapi import routing
  File "C:\Users\eye43\AppData\Local\Programs\Python\Python313\Lib\site-packages\fastapi\routing.py", line 24, in <module>
    from fastapi.dependencies.models import Dependant
  File "C:\Users\eye43\AppData\Local\Programs\Python\Python313\Lib\site-packages\fastapi\dependencies\models.py", line 3, in <module>
    from fastapi.security.base import SecurityBase
  File "C:\Users\eye43\AppData\Local\Programs\Python\Python313\Lib\site-packages\fastapi\security\__init__.py", line 1, in <module>
    from .api_key import APIKeyCookie as APIKeyCookie
  File "C:\Users\eye43\AppData\Local\Programs\Python\Python313\Lib\site-packages\fastapi\security\api_key.py", line 3, in <module>
    from fastapi.openapi.models import APIKey, APIKeyIn
  File "C:\Users\eye43\AppData\Local\Programs\Python\Python313\Lib\site-packages\fastapi\openapi\models.py", line 103, in <module>
    class Schema(BaseModel):
    ...<38 lines>...
            extra: str = "allow"
  File "C:\Users\eye43\AppData\Local\Programs\Python\Python313\Lib\site-packages\pydantic\main.py", line 286, in __new__
    cls.__try_update_forward_refs__()
    ~~~~~~~~~~~~~~~~~~~~~~~~~~~~~~~^^
  File "C:\Users\eye43\AppData\Local\Programs\Python\Python313\Lib\site-packages\pydantic\main.py", line 808, in __try_update_forward_refs__
    update_model_forward_refs(cls, cls.__fields__.values(), cls.__config__.json_encoders, localns, (NameError,))
    ~~~~~~~~~~~~~~~~~~~~~~~~~^^^^^^^^^^^^^^^^^^^^^^^^^^^^^^^^^^^^^^^^^^^^^^^^^^^^^^^^^^^^^^^^^^^^^^^^^^^^^^^^^^^
  File "C:\Users\eye43\AppData\Local\Programs\Python\Python313\Lib\site-packages\pydantic\typing.py", line 554, in update_model_forward_refs
    update_field_forward_refs(f, globalns=globalns, localns=localns)
    ~~~~~~~~~~~~~~~~~~~~~~~~~^^^^^^^^^^^^^^^^^^^^^^^^^^^^^^^^^^^^^^^
  File "C:\Users\eye43\AppData\Local\Programs\Python\Python313\Lib\site-packages\pydantic\typing.py", line 520, in update_field_forward_refs
    field.type_ = evaluate_forwardref(field.type_, globalns, localns or None)
                  ~~~~~~~~~~~~~~~~~~~^^^^^^^^^^^^^^^^^^^^^^^^^^^^^^^^^^^^^^^^
  File "C:\Users\eye43\AppData\Local\Programs\Python\Python313\Lib\site-packages\pydantic\typing.py", line 66, in evaluate_forwardref
    return cast(Any, type_)._evaluate(globalns, localns, set())
           ~~~~~~~~~~~~~~~~~~~~~~~~~~^^^^^^^^^^^^^^^^^^^^^^^^^^
TypeError: ForwardRef._evaluate() missing 1 required keyword-only argument: 'recursive_guard'
  - Captured at: 2025-10-13T17:01:12.056501+00:00
  - Suggested action: Investigate
  - Stderr preview:
    > Traceback (most recent call last):
    >   File "<frozen runpy>", line 198, in _run_module_as_main
    >   File "<frozen runpy>", line 88, in _run_code
    >   File "C:\Users\eye43\AppData\Local\Programs\Python\Python313\Lib\site-packages\pyright\__main__.py", line 1, in <module>
    >     from fastapi.cli import main
    > …

- [ ] `x_make_pypi_x` · `ruff_fix` — ruff_fix failed for x_make_pypi_x (exit 1) cwd: C:\x_runner_x\x_make_pypi_x command: C:\Users\eye43\AppData\Local\Programs\Python\Python313\python.exe -m ruff check . --fix --select ALL --ignore D,COM812,ISC001,T20 --line-length 88 --targe…
  - Command: `C:\Users\eye43\AppData\Local\Programs\Python\Python313\python.exe -m ruff check . --fix --select ALL --ignore D,COM812,ISC001,T20 --line-length 88 --target-version py311`
  - Exit: exit 1
  - Repo path: `C:\x_runner_x\x_make_pypi_x`
  - Tool version: ruff 0.14.0
  - Captured at: 2025-10-13T17:01:12.325826+00:00
  - Suggested action: Investigate
  - Stdout preview:
    > TC002 Move third-party import `x_0_make_all_x.manifest.ManifestEntry` into a type-checking block
    >   --> publish_flow.py:13:37
    >    |
    > 11 | from typing import Protocol, TypeVar, cast
    > 12 |
    > …

- [ ] `x_make_pypi_x` · `black` — black failed for x_make_pypi_x (exit 1) cwd: C:\x_runner_x\x_make_pypi_x command: C:\Users\eye43\AppData\Local\Programs\Python\Python313\python.exe -m black . --line-length 88 --target-version py311 --check --diff started_at: 2025-10-13T17…
  - Command: `C:\Users\eye43\AppData\Local\Programs\Python\Python313\python.exe -m black . --line-length 88 --target-version py311 --check --diff`
  - Exit: exit 1
  - Repo path: `C:\x_runner_x\x_make_pypi_x`
  - Tool version: python -m black, 25.9.0 (compiled: yes)
Python (CPython) 3.13.7
  - Captured at: 2025-10-13T17:01:13.646198+00:00
  - Suggested action: Investigate
  - Stdout preview:
    > --- C:\x_runner_x\x_make_pypi_x\publish_flow.py	2025-10-13 17:01:12.302995+00:00
    > +++ C:\x_runner_x\x_make_pypi_x\publish_flow.py	2025-10-13 17:01:13.410651+00:00
    > @@ -478,13 +478,11 @@
    >          "anc": context.ancillary_rel,
    >      }
    > …
  - Stderr preview:
    > would reformat C:\x_runner_x\x_make_pypi_x\publish_flow.py
    > 
    > Oh no! \U0001f4a5 \U0001f494 \U0001f4a5
    > 1 file would be reformatted, 1 file would be left unchanged.

- [ ] `x_make_pypi_x` · `ruff_check` — ruff_check failed for x_make_pypi_x (exit 1) cwd: C:\x_runner_x\x_make_pypi_x command: C:\Users\eye43\AppData\Local\Programs\Python\Python313\python.exe -m ruff check . --select ALL --ignore D,COM812,ISC001,T20 --line-length 88 --target-ve…
  - Command: `C:\Users\eye43\AppData\Local\Programs\Python\Python313\python.exe -m ruff check . --select ALL --ignore D,COM812,ISC001,T20 --line-length 88 --target-version py311`
  - Exit: exit 1
  - Repo path: `C:\x_runner_x\x_make_pypi_x`
  - Tool version: ruff 0.14.0
  - Captured at: 2025-10-13T17:01:13.756224+00:00
  - Suggested action: Investigate
  - Stdout preview:
    > TC002 Move third-party import `x_0_make_all_x.manifest.ManifestEntry` into a type-checking block
    >   --> publish_flow.py:13:37
    >    |
    > 11 | from typing import Protocol, TypeVar, cast
    > 12 |
    > …

- [ ] `x_make_pypi_x` · `mypy` — mypy failed for x_make_pypi_x (exit 1) cwd: C:\x_runner_x\x_make_pypi_x command: C:\Users\eye43\AppData\Local\Programs\Python\Python313\python.exe -m mypy . --strict --no-warn-unused-configs --show-error-codes --warn-return-any --warn-unre…
  - Command: `C:\Users\eye43\AppData\Local\Programs\Python\Python313\python.exe -m mypy . --strict --no-warn-unused-configs --show-error-codes --warn-return-any --warn-unreachable --disallow-any-unimported --disallow-any-expr --disallow-any-decorated --disallow-any-explicit`
  - Exit: exit 1
  - Repo path: `C:\x_runner_x\x_make_pypi_x`
  - Tool version: mypy 3.4.3 (compiled: yes)
  - Captured at: 2025-10-13T17:01:15.788688+00:00
  - Suggested action: Investigate
  - Stdout preview:
    > publish_flow.py:13: error: Cannot find implementation or library stub for module named "x_0_make_all_x.manifest"  [import-not-found]
    > publish_flow.py:13: note: See https://mypy.readthedocs.io/en/stable/running_mypy.html#missing-imports
    > publish_flow.py:14: error: Cannot find implementation or library stub for module named "x_make_common_x"  [import-not-found]
    > publish_flow.py:23: error: Explicit "Any" is not allowed  [explicit-any]
    > publish_flow.py:91: error: Argument 1 to "options_to_kwargs" becomes "Any" due to an unfollowed import  [no-any-unimported]
    > …

- [ ] `x_make_pypi_x` · `pyright` — pyright failed for x_make_pypi_x (exit 1) cwd: C:\x_runner_x\x_make_pypi_x command: C:\Users\eye43\AppData\Local\Programs\Python\Python313\python.exe -m pyright . --level error started_at: 2025-10-13T17:01:15.789404+00:00 duration: 0.306s …
  - Command: `C:\Users\eye43\AppData\Local\Programs\Python\Python313\python.exe -m pyright . --level error`
  - Exit: exit 1
  - Repo path: `C:\x_runner_x\x_make_pypi_x`
  - Tool version: <exit 1> Traceback (most recent call last):
  File "<frozen runpy>", line 198, in _run_module_as_main
  File "<frozen runpy>", line 88, in _run_code
  File "C:\Users\eye43\AppData\Local\Programs\Python\Python313\Lib\site-packages\pyright\__main__.py", line 1, in <module>
    from fastapi.cli import main
  File "C:\Users\eye43\AppData\Local\Programs\Python\Python313\Lib\site-packages\fastapi\__init__.py", line 7, in <module>
    from .applications import FastAPI as FastAPI
  File "C:\Users\eye43\AppData\Local\Programs\Python\Python313\Lib\site-packages\fastapi\applications.py", line 16, in <module>
    from fastapi import routing
  File "C:\Users\eye43\AppData\Local\Programs\Python\Python313\Lib\site-packages\fastapi\routing.py", line 24, in <module>
    from fastapi.dependencies.models import Dependant
  File "C:\Users\eye43\AppData\Local\Programs\Python\Python313\Lib\site-packages\fastapi\dependencies\models.py", line 3, in <module>
    from fastapi.security.base import SecurityBase
  File "C:\Users\eye43\AppData\Local\Programs\Python\Python313\Lib\site-packages\fastapi\security\__init__.py", line 1, in <module>
    from .api_key import APIKeyCookie as APIKeyCookie
  File "C:\Users\eye43\AppData\Local\Programs\Python\Python313\Lib\site-packages\fastapi\security\api_key.py", line 3, in <module>
    from fastapi.openapi.models import APIKey, APIKeyIn
  File "C:\Users\eye43\AppData\Local\Programs\Python\Python313\Lib\site-packages\fastapi\openapi\models.py", line 103, in <module>
    class Schema(BaseModel):
    ...<38 lines>...
            extra: str = "allow"
  File "C:\Users\eye43\AppData\Local\Programs\Python\Python313\Lib\site-packages\pydantic\main.py", line 286, in __new__
    cls.__try_update_forward_refs__()
    ~~~~~~~~~~~~~~~~~~~~~~~~~~~~~~~^^
  File "C:\Users\eye43\AppData\Local\Programs\Python\Python313\Lib\site-packages\pydantic\main.py", line 808, in __try_update_forward_refs__
    update_model_forward_refs(cls, cls.__fields__.values(), cls.__config__.json_encoders, localns, (NameError,))
    ~~~~~~~~~~~~~~~~~~~~~~~~~^^^^^^^^^^^^^^^^^^^^^^^^^^^^^^^^^^^^^^^^^^^^^^^^^^^^^^^^^^^^^^^^^^^^^^^^^^^^^^^^^^^
  File "C:\Users\eye43\AppData\Local\Programs\Python\Python313\Lib\site-packages\pydantic\typing.py", line 554, in update_model_forward_refs
    update_field_forward_refs(f, globalns=globalns, localns=localns)
    ~~~~~~~~~~~~~~~~~~~~~~~~~^^^^^^^^^^^^^^^^^^^^^^^^^^^^^^^^^^^^^^^
  File "C:\Users\eye43\AppData\Local\Programs\Python\Python313\Lib\site-packages\pydantic\typing.py", line 520, in update_field_forward_refs
    field.type_ = evaluate_forwardref(field.type_, globalns, localns or None)
                  ~~~~~~~~~~~~~~~~~~~^^^^^^^^^^^^^^^^^^^^^^^^^^^^^^^^^^^^^^^^
  File "C:\Users\eye43\AppData\Local\Programs\Python\Python313\Lib\site-packages\pydantic\typing.py", line 66, in evaluate_forwardref
    return cast(Any, type_)._evaluate(globalns, localns, set())
           ~~~~~~~~~~~~~~~~~~~~~~~~~~^^^^^^^^^^^^^^^^^^^^^^^^^^
TypeError: ForwardRef._evaluate() missing 1 required keyword-only argument: 'recursive_guard'
  - Captured at: 2025-10-13T17:01:16.095622+00:00
  - Suggested action: Investigate
  - Stderr preview:
    > Traceback (most recent call last):
    >   File "<frozen runpy>", line 198, in _run_module_as_main
    >   File "<frozen runpy>", line 88, in _run_code
    >   File "C:\Users\eye43\AppData\Local\Programs\Python\Python313\Lib\site-packages\pyright\__main__.py", line 1, in <module>
    >     from fastapi.cli import main
    > …

- [ ] `x_make_yahw_x` · `pyright` — pyright failed for x_make_yahw_x (exit 1) cwd: C:\x_runner_x\x_make_yahw_x command: C:\Users\eye43\AppData\Local\Programs\Python\Python313\python.exe -m pyright . --level error started_at: 2025-10-13T17:01:27.600934+00:00 duration: 0.305s …
  - Command: `C:\Users\eye43\AppData\Local\Programs\Python\Python313\python.exe -m pyright . --level error`
  - Exit: exit 1
  - Repo path: `C:\x_runner_x\x_make_yahw_x`
  - Tool version: <exit 1> Traceback (most recent call last):
  File "<frozen runpy>", line 198, in _run_module_as_main
  File "<frozen runpy>", line 88, in _run_code
  File "C:\Users\eye43\AppData\Local\Programs\Python\Python313\Lib\site-packages\pyright\__main__.py", line 1, in <module>
    from fastapi.cli import main
  File "C:\Users\eye43\AppData\Local\Programs\Python\Python313\Lib\site-packages\fastapi\__init__.py", line 7, in <module>
    from .applications import FastAPI as FastAPI
  File "C:\Users\eye43\AppData\Local\Programs\Python\Python313\Lib\site-packages\fastapi\applications.py", line 16, in <module>
    from fastapi import routing
  File "C:\Users\eye43\AppData\Local\Programs\Python\Python313\Lib\site-packages\fastapi\routing.py", line 24, in <module>
    from fastapi.dependencies.models import Dependant
  File "C:\Users\eye43\AppData\Local\Programs\Python\Python313\Lib\site-packages\fastapi\dependencies\models.py", line 3, in <module>
    from fastapi.security.base import SecurityBase
  File "C:\Users\eye43\AppData\Local\Programs\Python\Python313\Lib\site-packages\fastapi\security\__init__.py", line 1, in <module>
    from .api_key import APIKeyCookie as APIKeyCookie
  File "C:\Users\eye43\AppData\Local\Programs\Python\Python313\Lib\site-packages\fastapi\security\api_key.py", line 3, in <module>
    from fastapi.openapi.models import APIKey, APIKeyIn
  File "C:\Users\eye43\AppData\Local\Programs\Python\Python313\Lib\site-packages\fastapi\openapi\models.py", line 103, in <module>
    class Schema(BaseModel):
    ...<38 lines>...
            extra: str = "allow"
  File "C:\Users\eye43\AppData\Local\Programs\Python\Python313\Lib\site-packages\pydantic\main.py", line 286, in __new__
    cls.__try_update_forward_refs__()
    ~~~~~~~~~~~~~~~~~~~~~~~~~~~~~~~^^
  File "C:\Users\eye43\AppData\Local\Programs\Python\Python313\Lib\site-packages\pydantic\main.py", line 808, in __try_update_forward_refs__
    update_model_forward_refs(cls, cls.__fields__.values(), cls.__config__.json_encoders, localns, (NameError,))
    ~~~~~~~~~~~~~~~~~~~~~~~~~^^^^^^^^^^^^^^^^^^^^^^^^^^^^^^^^^^^^^^^^^^^^^^^^^^^^^^^^^^^^^^^^^^^^^^^^^^^^^^^^^^^
  File "C:\Users\eye43\AppData\Local\Programs\Python\Python313\Lib\site-packages\pydantic\typing.py", line 554, in update_model_forward_refs
    update_field_forward_refs(f, globalns=globalns, localns=localns)
    ~~~~~~~~~~~~~~~~~~~~~~~~~^^^^^^^^^^^^^^^^^^^^^^^^^^^^^^^^^^^^^^^
  File "C:\Users\eye43\AppData\Local\Programs\Python\Python313\Lib\site-packages\pydantic\typing.py", line 520, in update_field_forward_refs
    field.type_ = evaluate_forwardref(field.type_, globalns, localns or None)
                  ~~~~~~~~~~~~~~~~~~~^^^^^^^^^^^^^^^^^^^^^^^^^^^^^^^^^^^^^^^^
  File "C:\Users\eye43\AppData\Local\Programs\Python\Python313\Lib\site-packages\pydantic\typing.py", line 66, in evaluate_forwardref
    return cast(Any, type_)._evaluate(globalns, localns, set())
           ~~~~~~~~~~~~~~~~~~~~~~~~~~^^^^^^^^^^^^^^^^^^^^^^^^^^
TypeError: ForwardRef._evaluate() missing 1 required keyword-only argument: 'recursive_guard'
  - Captured at: 2025-10-13T17:01:27.905817+00:00
  - Suggested action: Investigate
  - Stderr preview:
    > Traceback (most recent call last):
    >   File "<frozen runpy>", line 198, in _run_module_as_main
    >   File "<frozen runpy>", line 88, in _run_code
    >   File "C:\Users\eye43\AppData\Local\Programs\Python\Python313\Lib\site-packages\pyright\__main__.py", line 1, in <module>
    >     from fastapi.cli import main
    > …

---

_Generated by x_make_github_visitor_x_; actionable items are tracked as unchecked tasks._
